<?xml version="1.0" ?>
<!-- =================================================================================== -->
<!-- |    This document was autogenerated by xacro from ur_gz.urdf.xacro               | -->
<!-- |    EDITING THIS FILE BY HAND IS NOT RECOMMENDED                                 | -->
<!-- =================================================================================== -->
<robot name="ur">
  <!--
    Base UR robot series xacro macro.

    NOTE this is NOT a URDF. It cannot directly be loaded by consumers
    expecting a flattened '.urdf' file. See the top-level '.xacro' for that
    (but note that .xacro must still be processed by the xacro command).

    This file models the base kinematic chain of a UR robot, which then gets
    parameterised by various configuration files to convert it into a UR3(e),
    UR5(e), UR10(e) or UR16e, etc.

    NOTE the default kinematic parameters (i.e., link lengths, frame locations,
    offsets, etc) do not correspond to any particular robot. They are defaults
    only. There WILL be non-zero offsets between the Forward Kinematics results
    in TF (i.e., robot_state_publisher) and the values reported by the Teach
    Pendant.

    For accurate (and robot-specific) transforms, the 'kinematics_parameters_file'
    parameter MUST point to a .yaml file containing the appropriate values for
    the targeted robot.

    If using the UniversalRobots/Universal_Robots_ROS_Driver, follow the steps
    described in the readme of that repository to extract the kinematic
    calibration from the controller and generate the required .yaml file.

    Main author of the migration to yaml configs Ludovic Delval.

    Contributors to previous versions (in no particular order)

     - Denis Stogl
     - Lovro Ivanov
     - Felix Messmer
     - Kelsey Hawkins
     - Wim Meeussen
     - Shaun Edwards
     - Nadia Hammoudeh Garcia
     - Dave Hershberger
     - G. vd. Hoorn
     - Philip Long
     - Dave Coleman
     - Miguel Prada
     - Mathias Luedtke
     - Marcel Schnirring
     - Felix von Drigalski
     - Felix Exner
     - Jimmy Da Silva
     - Ajit Krisshna N L
     - Muhammad Asif Rana
  -->
  <!-- create link fixed to the "world" -->
  <link name="world"/>
  <link name="tabletop"/>
  <joint name="tabletop_joint" type="fixed" dont_collapse="true">
    <origin rpy="0.0 0.0 0.0" xyz="0.0 0.0 0.0"/>
    <parent link="world"/>
    <child link="tabletop"/>
  </joint>
  <!-- <link name="ground_plane">
    <visual>
      <origin rpy="0 0 0" xyz="0 0 0"/>
      <geometry>
        <box size="5 5 0"/>
      </geometry>
      <material name="ground_white">
        <color rgba="1 1 1 0.5"/>
      </material>
    </visual>
    <collision>
      <origin rpy="0 0 0" xyz="0 0 0"/>
      <geometry>
        <box size="5 5 0"/>
      </geometry>
    </collision>
  </link>

  <joint name="ground_plane_joint" type="fixed">
    <origin xyz="$(arg x) $(arg y) $(arg z)" rpy="$(arg roll) $(arg pitch) $(arg yaw)" />
    <parent link="world"/>
    <child link="ground_plane"/>
  </joint> -->
  <!-- links -  main serial chain -->
  <!-- base_link serves as the root of the robot's kinematic tree. It follows REP-103
        conventions (i.e., X+ forward, Y+ left, Z+ up).
        Since some kinematic solvers forbid having inertia values attached to a root link, we've
        added the base_link_inertia link that carries the visual, collision and inertia
        information.
    -->
  <link name="base_link"/>
  <link name="base_link_inertia">
    <visual>
      <origin rpy="0.0 0.0 3.141592653589793" xyz="0.0 0.0 0.0"/>
      <geometry>
	      <mesh filename="/workspace/ws_aic/install/share/ur_description/meshes/ur5e/visual/base.dae"/>
      </geometry>
    </visual>
    <collision>
      <origin rpy="0.0 0.0 3.141592653589793" xyz="0.0 0.0 0.0"/>
      <geometry>
	      <mesh filename="/workspace/ws_aic/install/share/ur_description/meshes/ur5e/collision/base.stl"/>
      </geometry>
    </collision>
    <inertial>
      <mass value="4.0"/>
      <origin rpy="0 0 0" xyz="0 0 0"/>
      <inertia ixx="0.00443333156" ixy="0.0" ixz="0.0" iyy="0.00443333156" iyz="0.0" izz="0.0072"/>
    </inertial>
  </link>
  <link name="shoulder_link">
    <visual>
      <origin rpy="0.0 0.0 3.141592653589793" xyz="0.0 0.0 0.0"/>
      <geometry>
	      <mesh filename="/workspace/ws_aic/install/share/ur_description/meshes/ur5e/visual/shoulder.dae"/>
      </geometry>
    </visual>
    <collision>
      <origin rpy="0.0 0.0 3.141592653589793" xyz="0.0 0.0 0.0"/>
      <geometry>
	      <mesh filename="/workspace/ws_aic/install/share/ur_description/meshes/ur5e/collision/shoulder.stl"/>
      </geometry>
    </collision>
    <inertial>
      <mass value="3.761"/>
      <origin rpy="1.570796326794897 0 0" xyz="0.0 -0.00193 -0.02561"/>
      <inertia ixx="0.0070021" ixy="7.3e-07" ixz="-1.053e-05" iyy="0.00648091" iyz="0.00049994" izz="0.00657286"/>
    </inertial>
  </link>
  <link name="upper_arm_link">
    <visual>
      <origin rpy="1.5707963267948966 0.0 -1.5707963267948966" xyz="0.0 0.0 0.138"/>
      <geometry>
	      <mesh filename="/workspace/ws_aic/install/share/ur_description/meshes/ur5e/visual/upperarm.dae"/>
      </geometry>
    </visual>
    <collision>
      <origin rpy="1.5707963267948966 0.0 -1.5707963267948966" xyz="0.0 0.0 0.138"/>
      <geometry>
	      <mesh filename="/workspace/ws_aic/install/share/ur_description/meshes/ur5e/collision/upperarm.stl"/>
      </geometry>
    </collision>
    <inertial>
      <mass value="8.058"/>
      <origin rpy="0 0 0" xyz="-0.2125 0.0 0.11336"/>
      <inertia ixx="0.01505885" ixy="-5.4e-05" ixz="5.63e-06" iyy="0.33388086" iyz="-1.81e-06" izz="0.33247207"/>
    </inertial>
  </link>
  <link name="forearm_link">
    <visual>
      <origin rpy="1.5707963267948966 0.0 -1.5707963267948966" xyz="0.0 0.0 0.007"/>
      <geometry>
	      <mesh filename="/workspace/ws_aic/install/share/ur_description/meshes/ur5e/visual/forearm.dae"/>
      </geometry>
    </visual>
    <collision>
      <origin rpy="1.5707963267948966 0.0 -1.5707963267948966" xyz="0.0 0.0 0.007"/>
      <geometry>
	      <mesh filename="/workspace/ws_aic/install/share/ur_description/meshes/ur5e/collision/forearm.stl"/>
      </geometry>
    </collision>
    <inertial>
      <mass value="2.846"/>
      <origin rpy="0 0 0" xyz="-0.2422 0.0 0.0265"/>
      <inertia ixx="0.00399632" ixy="-1.365e-05" ixz="0.00137272" iyy="0.07879254" iyz="-6.6e-06" izz="0.0784851"/>
    </inertial>
  </link>
  <link name="wrist_1_link">
    <visual>
      <origin rpy="1.5707963267948966 0.0 0.0" xyz="0.0 0.0 -0.127"/>
      <geometry>
	      <mesh filename="/workspace/ws_aic/install/share/ur_description/meshes/ur5e/visual/wrist1.dae"/>
      </geometry>
    </visual>
    <collision>
      <origin rpy="1.5707963267948966 0.0 0.0" xyz="0.0 0.0 -0.127"/>
      <geometry>
	      <mesh filename="/workspace/ws_aic/install/share/ur_description/meshes/ur5e/collision/wrist1.stl"/>
      </geometry>
    </collision>
    <inertial>
      <mass value="1.37"/>
      <origin rpy="1.570796326794897 0 0" xyz="0.0 -0.01634 -0.0018"/>
      <inertia ixx="0.00165491" ixy="-2.82e-06" ixz="-4.38e-06" iyy="0.00135962" iyz="0.00010157" izz="0.00126279"/>
    </inertial>
  </link>
  <link name="wrist_2_link">
    <visual>
      <origin rpy="0.0 0.0 0.0" xyz="0.0 0.0 -0.0997"/>
      <geometry>
	      <mesh filename="/workspace/ws_aic/install/share/ur_description/meshes/ur5e/visual/wrist2.dae"/>
      </geometry>
    </visual>
    <collision>
      <origin rpy="0.0 0.0 0.0" xyz="0.0 0.0 -0.0997"/>
      <geometry>
	      <mesh filename="/workspace/ws_aic/install/share/ur_description/meshes/ur5e/collision/wrist2.stl"/>
      </geometry>
    </collision>
    <inertial>
      <mass value="1.3"/>
      <origin rpy="-1.570796326794897 0 0" xyz="0.0 0.01634 -0.0018"/>
      <inertia ixx="0.00135617" ixy="-2.74e-06" ixz="4.44e-06" iyy="0.00127827" iyz="-5.048e-05" izz="0.00096614"/>
    </inertial>
  </link>
  <link name="wrist_3_link">
    <visual>
      <origin rpy="1.5707963267948966 0.0 0.0" xyz="0.0 0.0 -0.0989"/>
      <geometry>
	      <mesh filename="/workspace/ws_aic/install/share/ur_description/meshes/ur5e/visual/wrist3.dae"/>
      </geometry>
    </visual>
    <collision>
      <origin rpy="1.5707963267948966 0.0 0.0" xyz="0.0 0.0 -0.0989"/>
      <geometry>
	      <mesh filename="/workspace/ws_aic/install/share/ur_description/meshes/ur5e/collision/wrist3.stl"/>
      </geometry>
    </collision>
    <inertial>
      <mass value="0.365"/>
      <origin rpy="0 0 0" xyz="0.0 0.0 -0.001159"/>
      <inertia ixx="0.00018694" ixy="6e-08" ixz="-1.7e-07" iyy="0.00018908" iyz="-9.2e-07" izz="0.00025756"/>
    </inertial>
  </link>
  <!-- base_joint fixes base_link to the environment -->
  <joint name="base_joint" type="fixed" dont_collapse="true">
    <origin rpy="0 0 0" xyz="0 0 0"/>
    <parent link="tabletop"/>
    <child link="base_link"/>
  </joint>
  <!-- joints - main serial chain -->
  <joint name="base_link-base_link_inertia" type="fixed" dont_collapse="true">
    <parent link="base_link"/>
    <child link="base_link_inertia"/>
    <!-- 'base_link' is REP-103 aligned (so X+ forward), while the internal
           frames of the robot/controller have X+ pointing backwards.
           Use the joint between 'base_link' and 'base_link_inertia' (a dummy
           link/frame) to introduce the necessary rotation over Z (of pi rad).
      -->
    <origin rpy="0 0 3.141592653589793" xyz="0 0 0"/>
  </joint>
  <joint name="shoulder_pan_joint" type="revolute">
    <parent link="base_link_inertia"/>
    <child link="shoulder_link"/>
    <origin rpy="0 0 0" xyz="0 0 0.1625"/>
    <axis xyz="0 0 1"/>
    <limit effort="150.0" lower="-6.283185307179586" upper="6.283185307179586" velocity="3.141592653589793"/>
    <dynamics damping="0" friction="0"/>
  </joint>
  <joint name="shoulder_lift_joint" type="revolute">
    <parent link="shoulder_link"/>
    <child link="upper_arm_link"/>
    <origin rpy="1.570796327 0 0" xyz="0 0 0"/>
    <axis xyz="0 0 1"/>
    <limit effort="150.0" lower="-6.283185307179586" upper="6.283185307179586" velocity="3.141592653589793"/>
    <dynamics damping="0" friction="0"/>
  </joint>
  <joint name="elbow_joint" type="revolute">
    <parent link="upper_arm_link"/>
    <child link="forearm_link"/>
    <origin rpy="0 0 0" xyz="-0.425 0 0"/>
    <axis xyz="0 0 1"/>
    <limit effort="150.0" lower="-3.141592653589793" upper="3.141592653589793" velocity="3.141592653589793"/>
    <dynamics damping="0" friction="0"/>
  </joint>
  <joint name="wrist_1_joint" type="revolute">
    <parent link="forearm_link"/>
    <child link="wrist_1_link"/>
    <origin rpy="0 0 0" xyz="-0.3922 0 0.1333"/>
    <axis xyz="0 0 1"/>
    <limit effort="28.0" lower="-6.283185307179586" upper="6.283185307179586" velocity="3.141592653589793"/>
    <dynamics damping="0" friction="0"/>
  </joint>
  <joint name="wrist_2_joint" type="revolute">
    <parent link="wrist_1_link"/>
    <child link="wrist_2_link"/>
    <origin rpy="1.570796327 0 0" xyz="0 -0.0997 -2.044881182297852e-11"/>
    <axis xyz="0 0 1"/>
    <limit effort="28.0" lower="-6.283185307179586" upper="6.283185307179586" velocity="3.141592653589793"/>
    <dynamics damping="0" friction="0"/>
  </joint>
  <joint name="wrist_3_joint" type="revolute">
    <parent link="wrist_2_link"/>
    <child link="wrist_3_link"/>
    <origin rpy="1.570796326589793 3.141592653589793 3.141592653589793" xyz="0 0.0996 -2.042830148012698e-11"/>
    <axis xyz="0 0 1"/>
    <limit effort="28.0" lower="-6.283185307179586" upper="6.283185307179586" velocity="3.141592653589793"/>
    <dynamics damping="0" friction="0"/>
  </joint>
  <link name="ft_frame"/>
  <joint name="wrist_3_link_ft_frame" type="fixed" dont_collapse="true">
    <parent link="wrist_3_link"/>
    <child link="ft_frame"/>
    <origin rpy="3.141592653589793 0 0" xyz="0 0 0"/>
  </joint>
  <!-- ROS-Industrial 'base' frame - base_link to UR 'Base' Coordinates transform -->
  <link name="base"/>
  <joint name="base_link_base_fixed_joint" type="fixed" dont_collapse="true">
    <!-- Note the rotation over Z of pi radians - as base_link is REP-103
           aligned (i.e., has X+ forward, Y+ left and Z+ up), this is needed
           to correctly align 'base' with the 'Base' coordinate system of
           the UR controller.
      -->
    <origin rpy="0 0 3.141592653589793" xyz="0 0 0"/>
    <parent link="base_link"/>
    <child link="base"/>
  </joint>
  <!-- ROS-Industrial 'flange' frame - attachment point for EEF models -->
  <link name="flange"/>
  <joint name="wrist_3_flange" type="fixed" dont_collapse="true">
    <parent link="wrist_3_link"/>
    <child link="flange"/>
    <origin rpy="0 -1.5707963267948966 -1.5707963267948966" xyz="0 0 0"/>
  </joint>
  <!-- ROS-Industrial 'tool0' frame - all-zeros tool frame -->
  <link name="tool0"/>
  <joint name="flange_tool0" type="fixed" dont_collapse="true">
    <!-- default toolframe - X+ left, Y+ up, Z+ front -->
    <origin rpy="1.5707963267948966 0 1.5707963267948966" xyz="0 0 0"/>
    <parent link="flange"/>
    <child link="tool0"/>
  </joint>
  <link name="ati_base_link">
    <inertial>
      <origin rpy="0 0 0" xyz="0 0 0"/>
      <mass value="0.36"/>
      <inertia ixx="0.0017389750000000002" ixy="0" ixz="0" iyy="0.0017389750000000002" iyz="0" izz="0.0002521499999999999"/>
    </inertial>
    <visual name="axia_ft_sensor_visual">
      <origin rpy="0 0 0" xyz="0 0 0"/>
      <geometry>
	      <mesh filename="/workspace/ws_aic/src/aic/aic_assets/models/axia80_m20/axia_ft_sensor_visual.dae"/>
      </geometry>
    </visual>
    <collision name="axia80_m20_collider_cylinder">
      <origin rpy="3.141593 0.0 0.0" xyz="0.0 -0.000004 0.012699"/>
      <geometry>
        <cylinder length="0.025399" radius="0.041519"/>
      </geometry>
    </collision>
    <collision name="axia80_m20001_collider_cylinder">
      <origin rpy="-1.570796 0 0" xyz="0.0 0.041828 0.018432"/>
      <geometry>
        <cylinder length="0.016717" radius="0.006027"/>
      </geometry>
    </collision>
  </link>
  <joint name="ati_attach_joint" type="fixed" dont_collapse="true">
    <origin rpy="0 0 0" xyz="0 0 0.0245"/>
    <parent link="ati_base_link"/>
    <child link="ati_tool_link"/>
  </joint>
  <link name="ati_tool_link">
    <inertial>
      <origin rpy="0 0 0" xyz="0 0 0"/>
      <mass value="0.001"/>
      <inertia ixx="0.000001" ixy="0" ixz="0" iyy="0.000001" iyz="0" izz="0.000001"/>
    </inertial>
  </link>
  <link name="cam_mount_cam_mount_link">
    <inertial>
      <origin rpy="0 0 0" xyz="0 0 0"/>
      <mass value="0.001"/>
      <inertia ixx="0.000001" ixy="0" ixz="0" iyy="0.000001" iyz="0" izz="0.000001"/>
    </inertial>
    <visual name="cam_mount_visual">
      <geometry>
        <mesh filename="/workspace/ws_aic/src/aic/aic_assets/models/camera_mount/cam_mount_visual.dae"/>
      </geometry>
    </visual>
    <collision name="cam_mount_collider_cylinder">
      <origin rpy="0.0 0.0 0.0" xyz="0.0 0.0 0.0215"/>
      <geometry>
        <cylinder length="0.01" radius="0.06"/>
      </geometry>
    </collision>
    <collision name="cam_mount_collider_cylinder.001">
      <origin rpy="0.0 0.0 0.0" xyz="0.0 0.0 0.012638"/>
      <geometry>
        <cylinder length="0.025275" radius="0.030383"/>
      </geometry>
    </collision>
    <!-- TODO(anyone): Update the colliders to match the [-60, 0, +60] cameras. -->
    <collision name="cam_mount003_collider_box">
      <origin rpy="0.0 0.0 -1.570796" xyz="0.000252 -0.068974 0.0193"/>
      <geometry>
        <box size="0.055675 0.036898 0.0044"/>
      </geometry>
    </collision>
    <collision name="cam_mount003_collider_box.001">
      <origin rpy="0.0 1.308997 -1.570796" xyz="0.000189 -0.100267 0.003926"/>
      <geometry>
        <box size="0.035256 0.04325 0.00858"/>
      </geometry>
    </collision>
    <collision name="cam_mount003_collider_box.002">
      <origin rpy="0.0 0.479966 -1.570796" xyz="0.000252 -0.076575 0.007442"/>
      <geometry>
        <box size="0.059567 0.036898 0.010442"/>
      </geometry>
    </collision>
    <collision name="cam_mount003_collider_box.003">
      <origin rpy="0.0 0.0 -0.523599" xyz="0.059859 -0.034268 0.0193"/>
      <geometry>
        <box size="0.055675 0.036898 0.0044"/>
      </geometry>
    </collision>
    <collision name="cam_mount003_collider_box.004">
      <origin rpy="0.0 1.308997 -0.523599" xyz="0.086928 -0.04997 0.003926"/>
      <geometry>
        <box size="0.035256 0.04325 0.00858"/>
      </geometry>
    </collision>
    <collision name="cam_mount003_collider_box.005">
      <origin rpy="0.0 0.479965 -0.523599" xyz="0.06619 -0.037924 0.007593"/>
      <geometry>
        <box size="0.060221 0.036898 0.010442"/>
      </geometry>
    </collision>
    <collision name="cam_mount003_collider_box.006">
      <origin rpy="0.0 -0.0 -2.617994" xyz="-0.059607 -0.034705 0.0193"/>
      <geometry>
        <box size="0.055675 0.036898 0.0044"/>
      </geometry>
    </collision>
    <collision name="cam_mount003_collider_box.007">
      <origin rpy="0.0 1.308997 -2.617994" xyz="-0.08674 -0.050297 0.003926"/>
      <geometry>
        <box size="0.035256 0.04325 0.00858"/>
      </geometry>
    </collision>
    <collision name="cam_mount003_collider_box.008">
      <origin rpy="0.0 0.479965 -2.617994" xyz="-0.066139 -0.038476 0.007473"/>
      <geometry>
        <box size="0.0597 0.036898 0.010442"/>
      </geometry>
    </collision>
  </link>
  <link name="left_camera_camera_link">
    <inertial>
      <origin rpy="0 0 0" xyz="0 0 0"/>
      <mass value="0.001"/>
      <inertia ixx="0.00002083" ixy="0" ixz="0" iyy="0.00002083" iyz="0" izz="0.000015"/>
    </inertial>
    <visual name="basler_cam_visual">
      <origin rpy="-1.5708 0 -1.5708" xyz="0 0 0"/>
      <geometry>
	      <mesh filename="/workspace/ws_aic/src/aic/aic_assets/models/basler_camera/basler_cam_visual.dae"/>
      </geometry>
    </visual>
    <collision name="body_collider_box">
      <origin rpy="0 0 0" xyz="0.00255 0 0.0145"/>
      <geometry>
        <box size="0.0483 0.029 0.029"/>
      </geometry>
    </collision>
    <collision name="lens_collider_cylinder">
      <origin rpy="0 1.5708 0" xyz="0.04833 0 0.0145"/>
      <geometry>
        <cylinder length="0.04326" radius="0.015631"/>
      </geometry>
    </collision>
  </link>
  <link name="left_camera_sensor_link">
    <!-- inertial property required for valid conversion to SDF,
        so we set a tiny mass and M.O.I. here -->
    <inertial>
      <origin rpy="0 0 0" xyz="0 0 0"/>
      <mass value="0.001"/>
      <inertia ixx="0.000001" ixy="0" ixz="0" iyy="0.000001" iyz="0" izz="0.000001"/>
    </inertial>
  </link>
  <!-- The sensor surface is 21.174mm in front of the M3 mounting hole -->
  <joint name="left_camera_attach_sensor_link" type="fixed" dont_collapse="true">
    <origin rpy="0 0 0" xyz="0.02174 0 0.0145"/>
    <parent link="left_camera_camera_link"/>
    <child link="left_camera_sensor_link"/>
  </joint>
  <link name="left_camera_optical">
    <!-- inertial property required for valid conversion to SDF,
        so we set a tiny mass and M.O.I. here -->
    <inertial>
      <origin rpy="0 0 0" xyz="0 0 0"/>
      <mass value="0.001"/>
      <inertia ixx="0.000001" ixy="0" ixz="0" iyy="0.000001" iyz="0" izz="0.000001"/>
    </inertial>
  </link>
  <!-- The optical frame is at the same origin as the sensor frame
         but is Z=forward, rather than Z=up. -->
  <joint name="left_camera_attach_optical" type="fixed" dont_collapse="true">
    <origin rpy="-1.5708 0 -1.5708" xyz="0 0 0"/>
    <parent link="left_camera_sensor_link"/>
    <child link="left_camera_optical"/>
  </joint>
  <link name="center_camera_camera_link">
    <inertial>
      <origin rpy="0 0 0" xyz="0 0 0"/>
      <mass value="0.001"/>
      <inertia ixx="0.00002083" ixy="0" ixz="0" iyy="0.00002083" iyz="0" izz="0.000015"/>
    </inertial>
    <visual name="basler_cam_visual">
      <origin rpy="-1.5708 0 -1.5708" xyz="0 0 0"/>
      <geometry>
        <mesh filename="/workspace/ws_aic/src/aic/aic_assets/models/basler_camera/basler_cam_visual.dae"/>
      </geometry>
    </visual>
    <collision name="body_collider_box">
      <origin rpy="0 0 0" xyz="0.00255 0 0.0145"/>
      <geometry>
        <box size="0.0483 0.029 0.029"/>
      </geometry>
    </collision>
    <collision name="lens_collider_cylinder">
      <origin rpy="0 1.5708 0" xyz="0.04833 0 0.0145"/>
      <geometry>
        <cylinder length="0.04326" radius="0.015631"/>
      </geometry>
    </collision>
  </link>
  <link name="center_camera_sensor_link">
    <!-- inertial property required for valid conversion to SDF,
        so we set a tiny mass and M.O.I. here -->
    <inertial>
      <origin rpy="0 0 0" xyz="0 0 0"/>
      <mass value="0.001"/>
      <inertia ixx="0.000001" ixy="0" ixz="0" iyy="0.000001" iyz="0" izz="0.000001"/>
    </inertial>
  </link>
  <!-- The sensor surface is 21.174mm in front of the M3 mounting hole -->
  <joint name="center_camera_attach_sensor_link" type="fixed" dont_collapse="true">
    <origin rpy="0 0 0" xyz="0.02174 0 0.0145"/>
    <parent link="center_camera_camera_link"/>
    <child link="center_camera_sensor_link"/>
  </joint>
  <link name="center_camera_optical">
    <!-- inertial property required for valid conversion to SDF,
        so we set a tiny mass and M.O.I. here -->
    <inertial>
      <origin rpy="0 0 0" xyz="0 0 0"/>
      <mass value="0.001"/>
      <inertia ixx="0.000001" ixy="0" ixz="0" iyy="0.000001" iyz="0" izz="0.000001"/>
    </inertial>
  </link>
  <!-- The optical frame is at the same origin as the sensor frame
         but is Z=forward, rather than Z=up. -->
  <joint name="center_camera_attach_optical" type="fixed" dont_collapse="true">
    <origin rpy="-1.5708 0 -1.5708" xyz="0 0 0"/>
    <parent link="center_camera_sensor_link"/>
    <child link="center_camera_optical"/>
  </joint>
  <link name="right_camera_camera_link">
    <inertial>
      <origin rpy="0 0 0" xyz="0 0 0"/>
      <mass value="0.001"/>
      <inertia ixx="0.00002083" ixy="0" ixz="0" iyy="0.00002083" iyz="0" izz="0.000015"/>
    </inertial>
    <visual name="basler_cam_visual">
      <origin rpy="-1.5708 0 -1.5708" xyz="0 0 0"/>
      <geometry>
	      <mesh filename="/workspace/ws_aic/src/aic/aic_assets/models/basler_camera/basler_cam_visual.dae"/>
      </geometry>
    </visual>
    <collision name="body_collider_box">
      <origin rpy="0 0 0" xyz="0.00255 0 0.0145"/>
      <geometry>
        <box size="0.0483 0.029 0.029"/>
      </geometry>
    </collision>
    <collision name="lens_collider_cylinder">
      <origin rpy="0 1.5708 0" xyz="0.04833 0 0.0145"/>
      <geometry>
        <cylinder length="0.04326" radius="0.015631"/>
      </geometry>
    </collision>
  </link>
  <link name="right_camera_sensor_link">
    <!-- inertial property required for valid conversion to SDF,
        so we set a tiny mass and M.O.I. here -->
    <inertial>
      <origin rpy="0 0 0" xyz="0 0 0"/>
      <mass value="0.001"/>
      <inertia ixx="0.000001" ixy="0" ixz="0" iyy="0.000001" iyz="0" izz="0.000001"/>
    </inertial>
  </link>
  <!-- The sensor surface is 21.174mm in front of the M3 mounting hole -->
  <joint name="right_camera_attach_sensor_link" type="fixed" dont_collapse="true">
    <origin rpy="0 0 0" xyz="0.02174 0 0.0145"/>
    <parent link="right_camera_camera_link"/>
    <child link="right_camera_sensor_link"/>
  </joint>
  <link name="right_camera_optical">
    <!-- inertial property required for valid conversion to SDF,
        so we set a tiny mass and M.O.I. here -->
    <inertial>
      <origin rpy="0 0 0" xyz="0 0 0"/>
      <mass value="0.001"/>
      <inertia ixx="0.000001" ixy="0" ixz="0" iyy="0.000001" iyz="0" izz="0.000001"/>
    </inertial>
  </link>
  <!-- The optical frame is at the same origin as the sensor frame
         but is Z=forward, rather than Z=up. -->
  <joint name="right_camera_attach_optical" type="fixed" dont_collapse="true">
    <origin rpy="-1.5708 0 -1.5708" xyz="0 0 0"/>
    <parent link="right_camera_sensor_link"/>
    <child link="right_camera_optical"/>
  </joint>
  <link name="gripper_hande_base_link">
    <inertial>
      <origin rpy="0 0 0" xyz="0 0 0"/>
      <mass value="1.0"/>
      <inertia ixx="0.1" ixy="0" ixz="0" iyy="0.1" iyz="0" izz="0.1"/>
    </inertial>
    <visual name="hande_base_visual">
      <origin rpy="0 0 0" xyz="0 0 0"/>
      <geometry>
        <mesh filename="/workspace/ws_aic/src/aic/aic_assets/models/robotiq_hand_e/hande_base_visual.dae"/>
      </geometry>
    </visual>
    <collision name="body_collider_cylinder">
      <origin rpy="3.141593 0.0 1.570796" xyz="0.0 0.0 0.06855"/>
      <geometry>
        <cylinder length="0.1131" radius="0.038"/>
      </geometry>
    </collision>
    <collision name="cylinder003_collider_cylinder">
      <origin rpy="0.0 0.0 0.0" xyz="0.0 0.0 0.006"/>
      <geometry>
        <cylinder length="0.012" radius="0.043"/>
      </geometry>
    </collision>
  </link>
  <link name="gripper_hande_finger_link_l">
    <inertial>
      <origin rpy="0 0 0" xyz="0 0 0"/>
      <mass value="0.001"/>
      <inertia ixx="0.0001" ixy="0" ixz="0" iyy="0.00009" iyz="0" izz="0.00003"/>
    </inertial>
    <visual name="hande_finger_visual">
      <origin rpy="0 0 0" xyz="-0.025 0 0"/>
      <geometry>
        <mesh filename="/workspace/ws_aic/src/aic/aic_assets/models/robotiq_hand_e/hande_finger_visual.dae"/>
      </geometry>
    </visual>
    <collision name="finger_collider_box">
      <origin rpy="0.0 0.0 0.0" xyz="0.007594999999999998 -0.00001 0.138138"/>
      <geometry>
        <box size="0.007839 0.021 0.028622"/>
      </geometry>
    </collision>
    <collision name="finger_collider_box001">
      <origin rpy="0.0 0.0 0.0" xyz="0.002999999999999999 -0.00001 0.16145"/>
      <geometry>
        <box size="0.006 0.021 0.021498"/>
      </geometry>
    </collision>
    <collision name="finger_collider_box002">
      <origin rpy="0.0 0.0 0.0" xyz="-0.010646000000000001 -0.015 0.124725"/>
      <geometry>
        <box size="0.044319 0.0075 0.003949"/>
      </geometry>
    </collision>
    <collision name="finger_collider_box003">
      <origin rpy="0.0 0.0 0.0" xyz="0.002045999999999999 -0.00954 0.129064"/>
      <geometry>
        <box size="0.017387 0.018419 0.009271"/>
      </geometry>
    </collision>
  </link>
  <link name="gripper_hande_finger_link_r">
    <inertial>
      <origin rpy="0 0 0" xyz="0 0 0"/>
      <mass value="0.001"/>
      <inertia ixx="0.0001" ixy="0" ixz="0" iyy="0.00009" iyz="0" izz="0.00003"/>
    </inertial>
    <visual name="hande_finger_visual">
      <origin rpy="0 0 3.14157" xyz="0.025 0 0"/>
      <geometry>
        <mesh filename="/workspace/ws_aic/src/aic/aic_assets/models/robotiq_hand_e/hande_finger_visual.dae"/>
      </geometry>
    </visual>
    <collision name="finger_collider_box">
      <origin rpy="0.0 0.0 0.0" xyz="-0.007594999999999998 -0.00001 0.138138"/>
      <geometry>
        <box size="0.007839 0.021 0.028622"/>
      </geometry>
    </collision>
    <collision name="finger_collider_box001">
      <origin rpy="0.0 0.0 0.0" xyz="-0.002999999999999999 -0.00001 0.16145"/>
      <geometry>
        <box size="0.006 0.021 0.021498"/>
      </geometry>
    </collision>
    <collision name="finger_collider_box002">
      <origin rpy="0.0 0.0 0.0" xyz="0.010646000000000001 -0.015 0.124725"/>
      <geometry>
        <box size="0.044319 0.0075 0.003949"/>
      </geometry>
    </collision>
    <collision name="finger_collider_box003">
      <origin rpy="0.0 0.0 0.0" xyz="-0.002045999999999999 -0.00954 0.129064"/>
      <geometry>
        <box size="0.017387 0.018419 0.009271"/>
      </geometry>
    </collision>
  </link>
  <joint name="gripper_left_finger_joint" type="prismatic">
    <origin rpy="0 0 0" xyz="0 0 0"/>
    <parent link="gripper_hande_base_link"/>
    <child link="gripper_hande_finger_link_l"/>
    <axis xyz="1 0 0"/>
    <limit effort="130" lower="0.0" upper="0.025" velocity="0.05"/>
  </joint>
  <joint name="gripper_right_finger_joint" type="prismatic">
    <origin rpy="0 0 0" xyz="0 0 0"/>
    <parent link="gripper_hande_base_link"/>
    <child link="gripper_hande_finger_link_r"/>
    <axis xyz="-1 0 0"/>
    <limit effort="130" lower="0.0" upper="0.025" velocity="0.05"/>
    <mimic joint="gripper_left_finger_joint" multiplier="1" offset="0"/>
  </joint>
  <link name="gripper_tcp"/>
  <joint name="gripper_attach_tool_frame" type="fixed" dont_collapse="true">
    <origin rpy="0 0 0" xyz="0 0 0.172"/>
    <parent link="gripper_hande_base_link"/>
    <child link="gripper_tcp"/>
  </joint>
  <joint name="attach_cam_mount" type="fixed" dont_collapse="true">
    <origin rpy="0 0 0" xyz="0 0 -.0265"/>
    <parent link="tool0"/>
    <child link="cam_mount_cam_mount_link"/>
  </joint>
  <joint name="attach_ft_sensor_joint" type="fixed" dont_collapse="true">
    <origin rpy="0 0 0" xyz="0 0 0.0265"/>
    <parent link="cam_mount_cam_mount_link"/>
    <child link="ati_base_link"/>
  </joint>
  <!-- *******************
       ** center_camera **
       ******************* -->
  <joint name="attach_center_camera" type="fixed" dont_collapse="true">
    <origin rpy="0 -1.30899630 1.57079623" xyz="0 -0.1077 -.00719"/>
    <parent link="cam_mount_cam_mount_link"/>
    <child link="center_camera_camera_link"/>
  </joint>
  <!-- *****************
       ** left_camera **
       ***************** -->
  <joint name="attach_left_camera" type="fixed" dont_collapse="true">
    <origin rpy="0 -1.30899630 0.523599027" xyz="-0.09326 -0.053843 -0.007188"/>
    <parent link="cam_mount_cam_mount_link"/>
    <child link="left_camera_camera_link"/>
  </joint>
  <!-- ******************
       ** right_camera **
       ****************** -->
  <joint name="attach_right_camera" type="fixed" dont_collapse="true">
    <origin rpy="0 -1.30899630 2.61799343" xyz="0.09326 -0.053843 -0.007188"/>
    <parent link="cam_mount_cam_mount_link"/>
    <child link="right_camera_camera_link"/>
  </joint>
  <joint name="attach_gripper" type="fixed" dont_collapse="true">
    <origin rpy="0 0 0" xyz="0 0 0"/>
    <parent link="ati_tool_link"/>
    <child link="gripper_hande_base_link"/>
  </joint>
</robot>
